Workbook

Sheet Raw Sales Transaction
A1: Transaction ID | B1: Date | C1: Branch | D1: Sales Rep | E1: Customer Name | F1: Product Code | G1: Product Name | H1: Qty | I1: Unit Price | J1: Discount | K1: Total Sales | L1: Payment Method | M1: Payment Status | N1: Channel
A2: TRX-1086 | B2: 2026-07-14 | C2: Cibubur | D2: Taufik Hidayat | E2: Galih Ramadhan | F2: P001 | G2: NMAX | H2: 1 | I2: 33500000 | J2: 1675000 | K2: 31825000 | L2: Kredit - Mandiri Tunas | M2: Lunas | N2: Pameran
A3: TRX-1192 | B3: 2026-07-16 | C3: Sukabumi | D3: Vino Bastian G. | E3: Made Ramadhan | F3: P001 | G3: NMAX | H3: 1 | I3: 33500000 | J3: 1005000 | K3: 32495000 | L3: Debit/Transfer | M3: Lunas | N3: Online - Website
A4: TRX-1108 | B4: 15 Juli 2026 | C4: Depok | D4: Joko Widodo S. | E4: Putra Hidayat | F4: P010 | G4: Freego | H4: 1 | I4: 22300000 | J4: 669000 | K4: 21631000 | L4: Cash | M4: Lunas | N4: Referral
A5: TRX-1106 | B5: 15/07/2026 | C5: Depok | D5: Lina Marlina | E5: Hana Anggraini | F5: P008 | G5: MX King | H5: 1 | I5: 24600000 | J5: 0 | K5: 24600000 | L5: Kredit - Adira | M5: Lunas | N5: Online - Website
A6: TRX-1124 | B6: 15/07/2026 | C6: Jakarta Selatan | D6: Fajar Nugraha | E6: Putra Saputra | F6: P007 | G6: XSR 155 | H6: 1 | I6: 41000000 | J6: 0 | K6: 41000000 | L6: Debit/Transfer | M6: Lunas | N6: Online - Website
A7: TRX-1094 | B7: 2026-07-14 | C7: Sukabumi | D7: Hadi Santoso | E7: Galih Kusuma | F7: P001 | G7: NMAX | H7: 1 | I7: 33500000 | J7: 1005000 | K7: 32495000 | L7: Cash | M7: Lunas | N7: Pameran
A8: TRX-1236 | B8: 2026-07-17 | C8: Cibubur | D8: Umi Kalsum | E8: Putra Kusuma | F8: P005 | G8: Fazzio | H8: 1 | I8: 21500000 | J8: 645000 | K8: 20855000 | L8: Kredit - FIF | M8: Lunas | N8: Online - Website
A9: TRX-1012 | B9: 2026-07-13 | C9: Bandung | D9: Puji Lestari | E9: Oscar Wijaya | F9: P006 | G9: Gear | H9: 1 | I9: 17800000 | J9: 890000 | K9: 16910000 | L9: Debit/Transfer | M9: Lunas | N9: Online - Website
A10: TRX-1148 | B10: 2026-07-16 | C10: Bekasi | D10: Sari Dewi | E10: Made Wijaya | F10: P001 | G10: NMAX | H10: 1 | I10: 33500000 | J10: 670000 | K10: 32830000 | L10: Cash | M10: Lunas | N10: Referral
A11: TRX-1213 | B11: 2026-07-17 | C11: Depok | D11: Eka Putri | E11: Ahmad Hidayat | F11: P001 | G11: NMAX | H11: 1 | I11: 33500000 | J11: 335000 | K11: 33165000 | L11: Kredit - FIF | M11: Lunas | N11: Showroom
A12: TRX-1340 | B12: 19/07/2026 | C12: Cibubur | D12: Kiki Amelia | E12: Eko Kusuma | F12: P007 | G12: XSR 155 | H12: 1 | I12: 41000000 | J12: 0 | K12: 41000000 | L12: Debit/Transfer | M12: DP | N12: Pameran
A13: TRX-1132 | B13: 2026-07-15 | C13: Karawang | D13: Kiki Amelia | E13: Citra Ramadhan | F13: P001 | G13: NMAX | H13: 1 | I13: 33500000 | J13: 1005000 | K13: 32495000 | L13: Debit/Transfer | M13: Proses Kredit | N13: Referral
... A61: TRX-1269 | B61: 2026-07-18 | C61: Serang | D61: Taufik Hidayat | E61: Eko Pratama | F61: P001 | G61: NMAX | H61: 1 | I61: 33500000 | J61: 670000 | K61: 32830000 | L61: Kredit - Mandiri Tunas | M61: Lunas | N61: Showroom
A62: TRX-1202 | B62: 17/07/2026 | C62: TANGERANG | E62: Fitri Anggraini | F62: P007 | G62: XSR 155 | H62: 1 | I62: 41000000 | J62: 0 | K62: 41000000 | L62: Kredit - FIF | M62: Proses Kredit | N62: Online - Website
A63: TRX-1013 | B63: 13/07/2026 | C63: Bandung | D63: Indah Permata | E63: Budi Hidayat | F63: P005 | G63: Fazzio | H63: 1 | I63: 21500000 | J63: 1075000 | K63: 20425000 | L63: Kredit - Adira | M63: Lunas | N63: Online - Website
A64: TRX-1200 | B64: 2026-07-17 | C64: Tangerang | D64: Mira Anjani | E64: Putra Hidayat | F64: P003 | G64: Lexi | H64: 1 | I64: 27400000 | J64: 1370000 | K64: 26030000 | L64: Kredit - Mandiri Tunas | M64: DP | N64: Referral
A65: TRX-1028 | B65: 13/07/2026 | C65: Cibubur | D65: Joko Widodo S. | E65: Tono Ramadhan | F65: P001 | G65: NMAX | H65: 2 | I65: 33500000 | J65: 0 | K65: 67000000 | L65: Debit/Transfer | M65: Lunas | N65: Showroom
A66: TRX-1103 | B66: 2026-07-15 | C66: Bekasi | D66: Vino Bastian G. | E66: Kevin Wijaya | F66: P002 | G66: Aerox | H66: 1 | I66: 29800000 | J66: 596000 | K66: 29204000 | L66: Kredit - Mandiri Tunas | M66: Lunas | N66: Online - Website
A67: TRX-1339 | B67: 2026-07-19 | C67: Cibubur | D67: Hadi Santoso | E67: Rendi Kusuma | F67: P003 | G67: Lexi | H67: 1 | I67: 27400000 | J67: 1370000 | K67: 26030000 | L67: Debit/Transfer | M67: Lunas | N67: Pameran
A68: TRX-1093 | B68: 14 Juli 2026 | C68: Sukabumi | D68: Hadi Santoso | E68: Dewi Hidayat | F68: P005 | G68: Fazzio | H68: 1 | I68: 21500000 | J68: 430000 | K68: 21070000 | L68: Kredit - Mandiri Tunas | M68: Lunas | N68: Referral
A69: TRX-1030 | B69: 13/07/2026 | C69: Sukabumi | D69: Lukman Hakim | E69: Jihan Firmansyah | F69: P006 | G69: Gear | H69: 1 | I69: 17800000 | J69: 178000 | K69: 17622000 | L69: Kredit - Adira | M69: Lunas | N69: Referral
A70: TRX-1059 | B70: 2026-07-14 | C70: Bogor | D70: Rangga Saputra | E70: Putra Hidayat | F70: P009 | G70: Grand Filano | H70: 1 | I70: 26900000 | J70: 807000 | K70: 26093000 | L70: Kredit - Adira | M70: Lunas | N70: Referral
A71: TRX-1193 | B71: 16/07/2026 | C71: Sukabumi | D71: Vino Bastian G. | E71: Lala Saputra | F71: P004 | G71: Mio | H71: 1 | I71: 18900000 | J71: 189000 | K71: 18711000 | L71: Debit/Transfer | M71: Lunas | N71: Pameran
A72: TRX-1223 | B72: 2026-07-17 | C72: Cikarang | D72: Kiki Amelia | E72: Tono Saputra | F72: P003 | G72: Lexi | H72: 1 | I72: 27400000 | J72: 0 | K72: 27400000 | L72: Cash | M72: DP | N72: Online - Website
A73: TRX-1278 | B73: 18/07/2026 | C73: Jakarta Selatan | D73: Lukman Hakim | E73: Budi Firmansyah | F73: P008 | G73: MX King | H73: 1 | I73: 24600000 | J73: 492000 | K73: 24108000 | L73: Cash | M73: Lunas | N73: Pameran
A74: TRX-1295 | B74: 18/07/2026 | C74: Sukabumi | D74: Indah Permata | E74: Kevin Ramadhan | F74: P003 | G74: Lexi | H74: 1 | I74: 27400000 | J74: 822000 | K74: 26578000 | L74: Kredit - FIF | M74: DP | N74: Referral
... A87: TRX-1052 | B87: 2026-07-14 | C87: Bandung | D87: Rangga Saputra | E87: Citra Ramadhan | F87: P002 | G87: Aerox | H87: 2 | I87: 29800000 | J87: 596000 | K87: 59004000 | L87: Kredit - Adira | M87: Lunas | N87: Online - Website
A88: TRX-1010 | B88: 13 Juli 2026 | C88: Depok | E88: Lala Lestari | F88: P010 | G88: Freego | H88: 1 | I88: 22300000 | J88: 0 | K88: 22300000 | L88: Cash | M88: Lunas | N88: Showroom
A89: TRX-1276 | B89: 2026-07-18 | C89: Jakarta Selatan | D89: Sari Dewi | E89: Siska Maharani | F89: P001 | G89: NMAX | H89: 1 | I89: 33500000 | J89: 335000 | K89: 0 | L89: Debit/Transfer | M89: Proses Kredit | N89: Showroom
A90: TRX-1017 | B90: 2026-07-13 | C90: Jakarta Timur | D90: Taufik Hidayat | E90: Putra Kusuma | F90: P009 | G90: Grand Filano | H90: 1 | I90: 26900000 | J90: 269000 | K90: 26631000 | L90: Debit/Transfer | M90: Lunas | N90: Showroom
A91: TRX-1248 | B91: 2026-07-18 | C91: Bandung | D91: Oki Setiawan | E91: Putra Maharani | F91: P007 | G91: XSR 155 | H91: 1 | I91: 41000000 | J91: 1230000 | K91: 39770000 | L91: Kredit - Mandiri Tunas | M91: Lunas | N91: Online - Website
A92: TRX-1001 | B92: 13 Juli 2026 | C92: Tangerang | D92: Taufik Hidayat | E92: Nia Saputra | F92: P002 | G92: Aerox | H92: 1 | I92: 29800000 | J92: 1490000 | K92: 28310000 | L92: Debit/Transfer | M92: Lunas | N92: Online - Website
A93: TRX-1159 | B93: 16 Juli 2026 | C93: Bandung | D93: Vino Bastian G. | E93: Kevin Pratama | F93: P002 | G93: Aerox | H93: 1 | I93: 29800000 | J93: 894000 | K93: 28906000 | L93: Kredit - Adira | M93: Lunas | N93: Pameran
A94: TRX-1139 | B94: 15/07/2026 | C94: Sukabumi | D94: Lukman Hakim | E94: Nia Pratama | F94: P004 | G94: Mio | H94: 1 | I94: 18900000 | J94: 0 | K94: 18900000 | L94: Cash | M94: Lunas | N94: Online - Website
A95: TRX-1063 | B95: 2026-07-14 | C95: Cikarang | D95: Kiki Amelia | E95: Irfan Ramadhan | F95: P003 | G95: Lexi | H95: 1 | I95: 27400000 | J95: 0 | K95: 27400000 | L95: Kredit - Mandiri Tunas | M95: Proses Kredit | N95: Online - Website
A96: TRX-1329 | B96: 2026-07-19 | C96: Jakarta Selatan | D96: Rudi Hartono | E96: Irfan Wijaya | F96: P010 | G96: Freego | H96: 1 | I96: 22300000 | J96: 446000 | K96: 21854000 | L96: Kredit - Adira | M96: Lunas | N96: Referral
A97: TRX-1160 | B97: 16/07/2026 | C97: Bandung | D97: Gita Ayu | E97: Nia Firmansyah | F97: P002 | G97: Aerox | H97: 1 | I97: 29800000 | J97: 894000 | K97: 28906000 | L97: Debit/Transfer | M97: Proses Kredit | N97: Referral
A98: TRX-1198 | B98: 16 Juli 2026 | C98: Sukabumi | D98: Lukman Hakim | E98: Jihan Lestari | F98: P004 | G98: Mio | H98: 1 | I98: 18900000 | J98: 567000 | K98: 18333000 | L98: Cash | M98: Proses Kredit | N98: Online - Website
A99: TRX-1071 | B99: 14/07/2026 | C99: Jakarta Timur | D99: Rudi Hartono | E99: Oscar Lestari | F99: P002 | G99: Aerox | H99: 1 | I99: 29800000 | J99: 596000 | K99: 29204000 | L99: Debit/Transfer | M99: Lunas | N99: Referral
...

Sheet Cleaning Sales Transaction
A1: Transaction ID | B1: Date | C1: Date Clean 1 | D1: Date Clean | E1: Branch | F1: Branch Clean | G1: Sales Rep | H1: Sales Rep Clean | I1: Customer Name | J1: Custumer Name Clean | K1: Product Code | L1: Product Name | M1: Qty | N1: Unit Price | O1: Discount | P1: Total Sales | Q1: Status Transaksi | R1: Payment Method | S1: Payment Status | T1: Channel | U1: Duplicate Check
A2: TRX-1086 | B2: 2026-07-14 | C2: =SUBSTITUTE(SUBSTITUTE(SUBSTITUTE(SUBSTITUTE(SUBSTITUTE(SUBSTITUTE(SUBSTITUTE(SUBSTITUTE(SUBSTITUTE(SUBSTITUTE(SUBSTITUTE(SUBSTITUTE(B2," Januari ","/01/")," Februari ","/02/")," Maret ","/03/")," April ","/04/")," Mei ","/05/")," Juni ","/06/")," Juli ","/07/")," Agustus ","/08/")," September ","/09/")," Oktober ","/10/")," November ","/11/")," Desember ","/12/") -> 2026-07-14 | D2: =IFERROR(DATE(VALUE(LEFT(C2,4)),VALUE(MID(C2,6,2)),VALUE(RIGHT(C2,2))),DATE(VALUE(RIGHT(C2,4)),VALUE(MID(C2,4,2)),VALUE(LEFT(C2,2)))) -> 46217 | E2: Cibubur | F2: =PROPER(TRIM(SUBSTITUTE(SUBSTITUTE(E2,"Jaksel","Jakarta Selatan"),"Tangerang Kota","Tangerang"))) -> Cibubur | G2: Taufik Hidayat | H2: =IF(G2="","Unknown",G2) -> Taufik Hidayat | I2: Galih Ramadhan | J2: =IF(I2="","Unknown",I2) -> Galih Ramadhan | K2: P001 | L2: NMAX | M2: 1 | N2: 33500000 | O2: 1675000 | P2: 31825000 | Q2: =IF(P2=0,"Batal/Refund","Normal") -> Normal | R2: Kredit - Mandiri Tunas | S2: Lunas | T2: Pameran | U2: =COUNTIF($A$2:$A$342,A2) -> 1
A3: TRX-1192 | B3: 2026-07-16 | C3: =SUBSTITUTE(SUBSTITUTE(SUBSTITUTE(SUBSTITUTE(SUBSTITUTE(SUBSTITUTE(SUBSTITUTE(SUBSTITUTE(SUBSTITUTE(SUBSTITUTE(SUBSTITUTE(SUBSTITUTE(B3," Januari ","/01/")," Februari ","/02/")," Maret ","/03/")," April ","/04/")," Mei ","/05/")," Juni ","/06/")," Juli ","/07/")," Agustus ","/08/")," September ","/09/")," Oktober ","/10/")," November ","/11/")," Desember ","/12/") -> 2026-07-16 | D3: =IFERROR(DATE(VALUE(LEFT(C3,4)),VALUE(MID(C3,6,2)),VALUE(RIGHT(C3,2))),DATE(VALUE(RIGHT(C3,4)),VALUE(MID(C3,4,2)),VALUE(LEFT(C3,2)))) -> 46219 | E3: Sukabumi | F3: =PROPER(TRIM(SUBSTITUTE(SUBSTITUTE(E3,"Jaksel","Jakarta Selatan"),"Tangerang Kota","Tangerang"))) -> Sukabumi | G3: Vino Bastian G. | H3: =IF(G3="","Unknown",G3) -> Vino Bastian G. | I3: Made Ramadhan | J3: =IF(I3="","Unknown",I3) -> Made Ramadhan | K3: P001 | L3: NMAX | M3: 1 | N3: 33500000 | O3: 1005000 | P3: 32495000 | Q3: =IF(P3=0,"Batal/Refund","Normal") -> Normal | R3: Debit/Transfer | S3: Lunas | T3: Online - Website | U3: =COUNTIF($A$2:$A$342,A3) -> 1
A4: TRX-1108 | B4: 15 Juli 2026 | C4: =SUBSTITUTE(SUBSTITUTE(SUBSTITUTE(SUBSTITUTE(SUBSTITUTE(SUBSTITUTE(SUBSTITUTE(SUBSTITUTE(SUBSTITUTE(SUBSTITUTE(SUBSTITUTE(SUBSTITUTE(B4," Januari ","/01/")," Februari ","/02/")," Maret ","/03/")," April ","/04/")," Mei ","/05/")," Juni ","/06/")," Juli ","/07/")," Agustus ","/08/")," September ","/09/")," Oktober ","/10/")," November ","/11/")," Desember ","/12/") -> 15/07/2026 | D4: =IFERROR(DATE(VALUE(LEFT(C4,4)),VALUE(MID(C4,6,2)),VALUE(RIGHT(C4,2))),DATE(VALUE(RIGHT(C4,4)),VALUE(MID(C4,4,2)),VALUE(LEFT(C4,2)))) -> 46218 | E4: Depok | F4: =PROPER(TRIM(SUBSTITUTE(SUBSTITUTE(E4,"Jaksel","Jakarta Selatan"),"Tangerang Kota","Tangerang"))) -> Depok | G4: Joko Widodo S. | H4: =IF(G4="","Unknown",G4) -> Joko Widodo S. | I4: Putra Hidayat | J4: =IF(I4="","Unknown",I4) -> Putra Hidayat | K4: P010 | L4: Freego | M4: 1 | N4: 22300000 | O4: 669000 | P4: 21631000 | Q4: =IF(P4=0,"Batal/Refund","Normal") -> Normal | R4: Cash | S4: Lunas | T4: Referral | U4: =COUNTIF($A$2:$A$342,A4) -> 1
A5: TRX-1106 | B5: 15/07/2026 | C5: =SUBSTITUTE(SUBSTITUTE(SUBSTITUTE(SUBSTITUTE(SUBSTITUTE(SUBSTITUTE(SUBSTITUTE(SUBSTITUTE(SUBSTITUTE(SUBSTITUTE(SUBSTITUTE(SUBSTITUTE(B5," Januari ","/01/")," Februari ","/02/")," Maret ","/03/")," April ","/04/")," Mei ","/05/")," Juni ","/06/")," Juli ","/07/")," Agustus ","/08/")," September ","/09/")," Oktober ","/10/")," November ","/11/")," Desember ","/12/") -> 15/07/2026 | D5: =IFERROR(DATE(VALUE(LEFT(C5,4)),VALUE(MID(C5,6,2)),VALUE(RIGHT(C5,2))),DATE(VALUE(RIGHT(C5,4)),VALUE(MID(C5,4,2)),VALUE(LEFT(C5,2)))) -> 46218 | E5: Depok | F5: =PROPER(TRIM(SUBSTITUTE(SUBSTITUTE(E5,"Jaksel","Jakarta Selatan"),"Tangerang Kota","Tangerang"))) -> Depok | G5: Lina Marlina | H5: =IF(G5="","Unknown",G5) -> Lina Marlina | I5: Hana Anggraini | J5: =IF(I5="","Unknown",I5) -> Hana Anggraini | K5: P008 | L5: MX King | M5: 1 | N5: 24600000 | O5: 0 | P5: 24600000 | Q5: =IF(P5=0,"Batal/Refund","Normal") -> Normal | R5: Kredit - Adira | S5: Lunas | T5: Online - Website | U5: =COUNTIF($A$2:$A$342,A5) -> 1
A6: TRX-1124 | B6: 15/07/2026 | C6: =SUBSTITUTE(SUBSTITUTE(SUBSTITUTE(SUBSTITUTE(SUBSTITUTE(SUBSTITUTE(SUBSTITUTE(SUBSTITUTE(SUBSTITUTE(SUBSTITUTE(SUBSTITUTE(SUBSTITUTE(B6," Januari ","/01/")," Februari ","/02/")," Maret ","/03/")," April ","/04/")," Mei ","/05/")," Juni ","/06/")," Juli ","/07/")," Agustus ","/08/")," September ","/09/")," Oktober ","/10/")," November ","/11/")," Desember ","/12/") -> 15/07/2026 | D6: =IFERROR(DATE(VALUE(LEFT(C6,4)),VALUE(MID(C6,6,2)),VALUE(RIGHT(C6,2))),DATE(VALUE(RIGHT(C6,4)),VALUE(MID(C6,4,2)),VALUE(LEFT(C6,2)))) -> 46218 | E6: Jakarta Selatan | F6: =PROPER(TRIM(SUBSTITUTE(SUBSTITUTE(E6,"Jaksel","Jakarta Selatan"),"Tangerang Kota","Tangerang"))) -> Jakarta Selatan | G6: Fajar Nugraha | H6: =IF(G6="","Unknown",G6) -> Fajar Nugraha | I6: Putra Saputra | J6: =IF(I6="","Unknown",I6) -> Putra Saputra | K6: P007 | L6: XSR 155 | M6: 1 | N6: 41000000 | O6: 0 | P6: 41000000 | Q6: =IF(P6=0,"Batal/Refund","Normal") -> Normal | R6: Debit/Transfer | S6: Lunas | T6: Online - Website | U6: =COUNTIF($A$2:$A$342,A6) -> 1
A7: TRX-1094 | B7: 2026-07-14 | C7: =SUBSTITUTE(SUBSTITUTE(SUBSTITUTE(SUBSTITUTE(SUBSTITUTE(SUBSTITUTE(SUBSTITUTE(SUBSTITUTE(SUBSTITUTE(SUBSTITUTE(SUBSTITUTE(SUBSTITUTE(B7," Januari ","/01/")," Februari ","/02/")," Maret ","/03/")," April ","/04/")," Mei ","/05/")," Juni ","/06/")," Juli ","/07/")," Agustus ","/08/")," September ","/09/")," Oktober ","/10/")," November ","/11/")," Desember ","/12/") -> 2026-07-14 | D7: =IFERROR(DATE(VALUE(LEFT(C7,4)),VALUE(MID(C7,6,2)),VALUE(RIGHT(C7,2))),DATE(VALUE(RIGHT(C7,4)),VALUE(MID(C7,4,2)),VALUE(LEFT(C7,2)))) -> 46217 | E7: Sukabumi | F7: =PROPER(TRIM(SUBSTITUTE(SUBSTITUTE(E7,"Jaksel","Jakarta Selatan"),"Tangerang Kota","Tangerang"))) -> Sukabumi | G7: Hadi Santoso | H7: =IF(G7="","Unknown",G7) -> Hadi Santoso | I7: Galih Kusuma | J7: =IF(I7="","Unknown",I7) -> Galih Kusuma | K7: P001 | L7: NMAX | M7: 1 | N7: 33500000 | O7: 1005000 | P7: 32495000 | Q7: =IF(P7=0,"Batal/Refund","Normal") -> Normal | R7: Cash | S7: Lunas | T7: Pameran | U7: =COUNTIF($A$2:$A$342,A7) -> 1
A8: TRX-1115 | B8: 15/07/2026 | C8: =SUBSTITUTE(SUBSTITUTE(SUBSTITUTE(SUBSTITUTE(SUBSTITUTE(SUBSTITUTE(SUBSTITUTE(SUBSTITUTE(SUBSTITUTE(SUBSTITUTE(SUBSTITUTE(SUBSTITUTE(B8," Januari ","/01/")," Februari ","/02/")," Maret ","/03/")," April ","/04/")," Mei ","/05/")," Juni ","/06/")," Juli ","/07/")," Agustus ","/08/")," September ","/09/")," Oktober ","/10/")," November ","/11/")," Desember ","/12/") -> 15/07/2026 | D8: =IFERROR(DATE(VALUE(LEFT(C8,4)),VALUE(MID(C8,6,2)),VALUE(RIGHT(C8,2))),DATE(VALUE(RIGHT(C8,4)),VALUE(MID(C8,4,2)),VALUE(LEFT(C8,2)))) -> 46218 | E8: Bogor | F8: =PROPER(TRIM(SUBSTITUTE(SUBSTITUTE(E8,"Jaksel","Jakarta Selatan"),"Tangerang Kota","Tangerang"))) -> Bogor | G8: Lukman Hakim | H8: =IF(G8="","Unknown",G8) -> Lukman Hakim | I8: Lala Firmansyah | J8: =IF(I8="","Unknown",I8) -> Lala Firmansyah | K8: P006 | L8: Gear | M8: 1 | N8: 17800000 | O8: 534000 | P8: 17266000 | Q8: =IF(P8=0,"Batal/Refund","Normal") -> Normal | R8: Kredit - Mandiri Tunas | S8: Lunas | T8: Online - Website | U8: =COUNTIF($A$2:$A$342,A8) -> 1
A9: TRX-1012 | B9: 2026-07-13 | C9: =SUBSTITUTE(SUBSTITUTE(SUBSTITUTE(SUBSTITUTE(SUBSTITUTE(SUBSTITUTE(SUBSTITUTE(SUBSTITUTE(SUBSTITUTE(SUBSTITUTE(SUBSTITUTE(SUBSTITUTE(B9," Januari ","/01/")," Februari ","/02/")," Maret ","/03/")," April ","/04/")," Mei ","/05/")," Juni ","/06/")," Juli ","/07/")," Agustus ","/08/")," September ","/09/")," Oktober ","/10/")," November ","/11/")," Desember ","/12/") -> 2026-07-13 | D9: =IFERROR(DATE(VALUE(LEFT(C9,4)),VALUE(MID(C9,6,2)),VALUE(RIGHT(C9,2))),DATE(VALUE(RIGHT(C9,4)),VALUE(MID(C9,4,2)),VALUE(LEFT(C9,2)))) -> 46216 | E9: Bandung | F9: =PROPER(TRIM(SUBSTITUTE(SUBSTITUTE(E9,"Jaksel","Jakarta Selatan"),"Tangerang Kota","Tangerang"))) -> Bandung | G9: Puji Lestari | H9: =IF(G9="","Unknown",G9) -> Puji Lestari | I9: Oscar Wijaya | J9: =IF(I9="","Unknown",I9) -> Oscar Wijaya | K9: P006 | L9: Gear | M9: 1 | N9: 17800000 | O9: 890000 | P9: 16910000 | Q9: =IF(P9=0,"Batal/Refund","Normal") -> Normal | R9: Debit/Transfer | S9: Lunas | T9: Online - Website | U9: =COUNTIF($A$2:$A$342,A9) -> 1
A10: TRX-1148 | B10: 2026-07-16 | C10: =SUBSTITUTE(SUBSTITUTE(SUBSTITUTE(SUBSTITUTE(SUBSTITUTE(SUBSTITUTE(SUBSTITUTE(SUBSTITUTE(SUBSTITUTE(SUBSTITUTE(SUBSTITUTE(SUBSTITUTE(B10," Januari ","/01/")," Februari ","/02/")," Maret ","/03/")," April ","/04/")," Mei ","/05/")," Juni ","/06/")," Juli ","/07/")," Agustus ","/08/")," September ","/09/")," Oktober ","/10/")," November ","/11/")," Desember ","/12/") -> 2026-07-16 | D10: =IFERROR(DATE(VALUE(LEFT(C10,4)),VALUE(MID(C10,6,2)),VALUE(RIGHT(C10,2))),DATE(VALUE(RIGHT(C10,4)),VALUE(MID(C10,4,2)),VALUE(LEFT(C10,2)))) -> 46219 | E10: Bekasi | F10: =PROPER(TRIM(SUBSTITUTE(SUBSTITUTE(E10,"Jaksel","Jakarta Selatan"),"Tangerang Kota","Tangerang"))) -> Bekasi | G10: Sari Dewi | H10: =IF(G10="","Unknown",G10) -> Sari Dewi | I10: Made Wijaya | J10: =IF(I10="","Unknown",I10) -> Made Wijaya | K10: P001 | L10: NMAX | M10: 1 | N10: 33500000 | O10: 670000 | P10: 32830000 | Q10: =IF(P10=0,"Batal/Refund","Normal") -> Normal | R10: Cash | S10: Lunas | T10: Referral | U10: =COUNTIF($A$2:$A$342,A10) -> 1
A11: TRX-1213 | B11: 2026-07-17 | C11: =SUBSTITUTE(SUBSTITUTE(SUBSTITUTE(SUBSTITUTE(SUBSTITUTE(SUBSTITUTE(SUBSTITUTE(SUBSTITUTE(SUBSTITUTE(SUBSTITUTE(SUBSTITUTE(SUBSTITUTE(B11," Januari ","/01/")," Februari ","/02/")," Maret ","/03/")," April ","/04/")," Mei ","/05/")," Juni ","/06/")," Juli ","/07/")," Agustus ","/08/")," September ","/09/")," Oktober ","/10/")," November ","/11/")," Desember ","/12/") -> 2026-07-17 | D11: =IFERROR(DATE(VALUE(LEFT(C11,4)),VALUE(MID(C11,6,2)),VALUE(RIGHT(C11,2))),DATE(VALUE(RIGHT(C11,4)),VALUE(MID(C11,4,2)),VALUE(LEFT(C11,2)))) -> 46220 | E11: Depok | F11: =PROPER(TRIM(SUBSTITUTE(SUBSTITUTE(E11,"Jaksel","Jakarta Selatan"),"Tangerang Kota","Tangerang"))) -> Depok | G11: Eka Putri | H11: =IF(G11="","Unknown",G11) -> Eka Putri | I11: Ahmad Hidayat | J11: =IF(I11="","Unknown",I11) -> Ahmad Hidayat | K11: P001 | L11: NMAX | M11: 1 | N11: 33500000 | O11: 335000 | P11: 33165000 | Q11: =IF(P11=0,"Batal/Refund","Normal") -> Normal | R11: Kredit - FIF | S11: Lunas | T11: Showroom | U11: =COUNTIF($A$2:$A$342,A11) -> 1
A12: TRX-1340 | B12: 19/07/2026 | C12: =SUBSTITUTE(SUBSTITUTE(SUBSTITUTE(SUBSTITUTE(SUBSTITUTE(SUBSTITUTE(SUBSTITUTE(SUBSTITUTE(SUBSTITUTE(SUBSTITUTE(SUBSTITUTE(SUBSTITUTE(B12," Januari ","/01/")," Februari ","/02/")," Maret ","/03/")," April ","/04/")," Mei ","/05/")," Juni ","/06/")," Juli ","/07/")," Agustus ","/08/")," September ","/09/")," Oktober ","/10/")," November ","/11/")," Desember ","/12/") -> 19/07/2026 | D12: =IFERROR(DATE(VALUE(LEFT(C12,4)),VALUE(MID(C12,6,2)),VALUE(RIGHT(C12,2))),DATE(VALUE(RIGHT(C12,4)),VALUE(MID(C12,4,2)),VALUE(LEFT(C12,2)))) -> 46222 | E12: Cibubur | F12: =PROPER(TRIM(SUBSTITUTE(SUBSTITUTE(E12,"Jaksel","Jakarta Selatan"),"Tangerang Kota","Tangerang"))) -> Cibubur | G12: Kiki Amelia | H12: =IF(G12="","Unknown",G12) -> Kiki Amelia | I12: Eko Kusuma | J12: =IF(I12="","Unknown",I12) -> Eko Kusuma | K12: P007 | L12: XSR 155 | M12: 1 | N12: 41000000 | O12: 0 | P12: 41000000 | Q12: =IF(P12=0,"Batal/Refund","Normal") -> Normal | R12: Debit/Transfer | S12: DP | T12: Pameran | U12: =COUNTIF($A$2:$A$342,A12) -> 1
A13: TRX-1132 | B13: 2026-07-15 | C13: =SUBSTITUTE(SUBSTITUTE(SUBSTITUTE(SUBSTITUTE(SUBSTITUTE(SUBSTITUTE(SUBSTITUTE(SUBSTITUTE(SUBSTITUTE(SUBSTITUTE(SUBSTITUTE(SUBSTITUTE(B13," Januari ","/01/")," Februari ","/02/")," Maret ","/03/")," April ","/04/")," Mei ","/05/")," Juni ","/06/")," Juli ","/07/")," Agustus ","/08/")," September ","/09/")," Oktober ","/10/")," November ","/11/")," Desember ","/12/") -> 2026-07-15 | D13: =IFERROR(DATE(VALUE(LEFT(C13,4)),VALUE(MID(C13,6,2)),VALUE(RIGHT(C13,2))),DATE(VALUE(RIGHT(C13,4)),VALUE(MID(C13,4,2)),VALUE(LEFT(C13,2)))) -> 46218 | E13: Karawang | F13: =PROPER(TRIM(SUBSTITUTE(SUBSTITUTE(E13,"Jaksel","Jakarta Selatan"),"Tangerang Kota","Tangerang"))) -> Karawang | G13: Kiki Amelia | H13: =IF(G13="","Unknown",G13) -> Kiki Amelia | I13: Citra Ramadhan | J13: =IF(I13="","Unknown",I13) -> Citra Ramadhan | K13: P001 | L13: NMAX | M13: 1 | N13: 33500000 | O13: 1005000 | P13: 32495000 | Q13: =IF(P13=0,"Batal/Refund","Normal") -> Normal | R13: Debit/Transfer | S13: Proses Kredit | T13: Referral | U13: =COUNTIF($A$2:$A$342,A13) -> 1
... A60: TRX-1269 | B60: 2026-07-18 | C60: =SUBSTITUTE(SUBSTITUTE(SUBSTITUTE(SUBSTITUTE(SUBSTITUTE(SUBSTITUTE(SUBSTITUTE(SUBSTITUTE(SUBSTITUTE(SUBSTITUTE(SUBSTITUTE(SUBSTITUTE(B60," Januari ","/01/")," Februari ","/02/")," Maret ","/03/")," April ","/04/")," Mei ","/05/")," Juni ","/06/")," Juli ","/07/")," Agustus ","/08/")," September ","/09/")," Oktober ","/10/")," November ","/11/")," Desember ","/12/") -> 2026-07-18 | D60: =IFERROR(DATE(VALUE(LEFT(C60,4)),VALUE(MID(C60,6,2)),VALUE(RIGHT(C60,2))),DATE(VALUE(RIGHT(C60,4)),VALUE(MID(C60,4,2)),VALUE(LEFT(C60,2)))) -> 46221 | E60: Serang | F60: =PROPER(TRIM(SUBSTITUTE(SUBSTITUTE(E60,"Jaksel","Jakarta Selatan"),"Tangerang Kota","Tangerang"))) -> Serang | G60: Taufik Hidayat | H60: =IF(G60="","Unknown",G60) -> Taufik Hidayat | I60: Eko Pratama | J60: =IF(I60="","Unknown",I60) -> Eko Pratama | K60: P001 | L60: NMAX | M60: 1 | N60: 33500000 | O60: 670000 | P60: 32830000 | Q60: =IF(P60=0,"Batal/Refund","Normal") -> Normal | R60: Kredit - Mandiri Tunas | S60: Lunas | T60: Showroom | U60: =COUNTIF($A$2:$A$342,A60) -> 1
A61: TRX-1202 | B61: 17/07/2026 | C61: =SUBSTITUTE(SUBSTITUTE(SUBSTITUTE(SUBSTITUTE(SUBSTITUTE(SUBSTITUTE(SUBSTITUTE(SUBSTITUTE(SUBSTITUTE(SUBSTITUTE(SUBSTITUTE(SUBSTITUTE(B61," Januari ","/01/")," Februari ","/02/")," Maret ","/03/")," April ","/04/")," Mei ","/05/")," Juni ","/06/")," Juli ","/07/")," Agustus ","/08/")," September ","/09/")," Oktober ","/10/")," November ","/11/")," Desember ","/12/") -> 17/07/2026 | D61: =IFERROR(DATE(VALUE(LEFT(C61,4)),VALUE(MID(C61,6,2)),VALUE(RIGHT(C61,2))),DATE(VALUE(RIGHT(C61,4)),VALUE(MID(C61,4,2)),VALUE(LEFT(C61,2)))) -> 46220 | E61: TANGERANG | F61: =PROPER(TRIM(SUBSTITUTE(SUBSTITUTE(E61,"Jaksel","Jakarta Selatan"),"Tangerang Kota","Tangerang"))) -> Tangerang | H61: =IF(G61="","Unknown",G61) -> Unknown | I61: Fitri Anggraini | J61: =IF(I61="","Unknown",I61) -> Fitri Anggraini | K61: P007 | L61: XSR 155 | M61: 1 | N61: 41000000 | O61: 0 | P61: 41000000 | Q61: =IF(P61=0,"Batal/Refund","Normal") -> Normal | R61: Kredit - FIF | S61: Proses Kredit | T61: Online - Website | U61: =COUNTIF($A$2:$A$342,A61) -> 1
A62: TRX-1013 | B62: 13/07/2026 | C62: =SUBSTITUTE(SUBSTITUTE(SUBSTITUTE(SUBSTITUTE(SUBSTITUTE(SUBSTITUTE(SUBSTITUTE(SUBSTITUTE(SUBSTITUTE(SUBSTITUTE(SUBSTITUTE(SUBSTITUTE(B62," Januari ","/01/")," Februari ","/02/")," Maret ","/03/")," April ","/04/")," Mei ","/05/")," Juni ","/06/")," Juli ","/07/")," Agustus ","/08/")," September ","/09/")," Oktober ","/10/")," November ","/11/")," Desember ","/12/") -> 13/07/2026 | D62: =IFERROR(DATE(VALUE(LEFT(C62,4)),VALUE(MID(C62,6,2)),VALUE(RIGHT(C62,2))),DATE(VALUE(RIGHT(C62,4)),VALUE(MID(C62,4,2)),VALUE(LEFT(C62,2)))) -> 46216 | E62: Bandung | F62: =PROPER(TRIM(SUBSTITUTE(SUBSTITUTE(E62,"Jaksel","Jakarta Selatan"),"Tangerang Kota","Tangerang"))) -> Bandung | G62: Indah Permata | H62: =IF(G62="","Unknown",G62) -> Indah Permata | I62: Budi Hidayat | J62: =IF(I62="","Unknown",I62) -> Budi Hidayat | K62: P005 | L62: Fazzio | M62: 1 | N62: 21500000 | O62: 1075000 | P62: 20425000 | Q62: =IF(P62=0,"Batal/Refund","Normal") -> Normal | R62: Kredit - Adira | S62: Lunas | T62: Online - Website | U62: =COUNTIF($A$2:$A$342,A62) -> 1
A63: TRX-1200 | B63: 2026-07-17 | C63: =SUBSTITUTE(SUBSTITUTE(SUBSTITUTE(SUBSTITUTE(SUBSTITUTE(SUBSTITUTE(SUBSTITUTE(SUBSTITUTE(SUBSTITUTE(SUBSTITUTE(SUBSTITUTE(SUBSTITUTE(B63," Januari ","/01/")," Februari ","/02/")," Maret ","/03/")," April ","/04/")," Mei ","/05/")," Juni ","/06/")," Juli ","/07/")," Agustus ","/08/")," September ","/09/")," Oktober ","/10/")," November ","/11/")," Desember ","/12/") -> 2026-07-17 | D63: =IFERROR(DATE(VALUE(LEFT(C63,4)),VALUE(MID(C63,6,2)),VALUE(RIGHT(C63,2))),DATE(VALUE(RIGHT(C63,4)),VALUE(MID(C63,4,2)),VALUE(LEFT(C63,2)))) -> 46220 | E63: Tangerang | F63: =PROPER(TRIM(SUBSTITUTE(SUBSTITUTE(E63,"Jaksel","Jakarta Selatan"),"Tangerang Kota","Tangerang"))) -> Tangerang | G63: Mira Anjani | H63: =IF(G63="","Unknown",G63) -> Mira Anjani | I63: Putra Hidayat | J63: =IF(I63="","Unknown",I63) -> Putra Hidayat | K63: P003 | L63: Lexi | M63: 1 | N63: 27400000 | O63: 1370000 | P63: 26030000 | Q63: =IF(P63=0,"Batal/Refund","Normal") -> Normal | R63: Kredit - Mandiri Tunas | S63: DP | T63: Referral | U63: =COUNTIF($A$2:$A$342,A63) -> 1
A64: TRX-1028 | B64: 13/07/2026 | C64: =SUBSTITUTE(SUBSTITUTE(SUBSTITUTE(SUBSTITUTE(SUBSTITUTE(SUBSTITUTE(SUBSTITUTE(SUBSTITUTE(SUBSTITUTE(SUBSTITUTE(SUBSTITUTE(SUBSTITUTE(B64," Januari ","/01/")," Februari ","/02/")," Maret ","/03/")," April ","/04/")," Mei ","/05/")," Juni ","/06/")," Juli ","/07/")," Agustus ","/08/")," September ","/09/")," Oktober ","/10/")," November ","/11/")," Desember ","/12/") -> 13/07/2026 | D64: =IFERROR(DATE(VALUE(LEFT(C64,4)),VALUE(MID(C64,6,2)),VALUE(RIGHT(C64,2))),DATE(VALUE(RIGHT(C64,4)),VALUE(MID(C64,4,2)),VALUE(LEFT(C64,2)))) -> 46216 | E64: Cibubur | F64: =PROPER(TRIM(SUBSTITUTE(SUBSTITUTE(E64,"Jaksel","Jakarta Selatan"),"Tangerang Kota","Tangerang"))) -> Cibubur | G64: Joko Widodo S. | H64: =IF(G64="","Unknown",G64) -> Joko Widodo S. | I64: Tono Ramadhan | J64: =IF(I64="","Unknown",I64) -> Tono Ramadhan | K64: P001 | L64: NMAX | M64: 2 | N64: 33500000 | O64: 0 | P64: 67000000 | Q64: =IF(P64=0,"Batal/Refund","Normal") -> Normal | R64: Debit/Transfer | S64: Lunas | T64: Showroom | U64: =COUNTIF($A$2:$A$342,A64) -> 1
A65: TRX-1103 | B65: 2026-07-15 | C65: =SUBSTITUTE(SUBSTITUTE(SUBSTITUTE(SUBSTITUTE(SUBSTITUTE(SUBSTITUTE(SUBSTITUTE(SUBSTITUTE(SUBSTITUTE(SUBSTITUTE(SUBSTITUTE(SUBSTITUTE(B65," Januari ","/01/")," Februari ","/02/")," Maret ","/03/")," April ","/04/")," Mei ","/05/")," Juni ","/06/")," Juli ","/07/")," Agustus ","/08/")," September ","/09/")," Oktober ","/10/")," November ","/11/")," Desember ","/12/") -> 2026-07-15 | D65: =IFERROR(DATE(VALUE(LEFT(C65,4)),VALUE(MID(C65,6,2)),VALUE(RIGHT(C65,2))),DATE(VALUE(RIGHT(C65,4)),VALUE(MID(C65,4,2)),VALUE(LEFT(C65,2)))) -> 46218 | E65: Bekasi | F65: =PROPER(TRIM(SUBSTITUTE(SUBSTITUTE(E65,"Jaksel","Jakarta Selatan"),"Tangerang Kota","Tangerang"))) -> Bekasi | G65: Vino Bastian G. | H65: =IF(G65="","Unknown",G65) -> Vino Bastian G. | I65: Kevin Wijaya | J65: =IF(I65="","Unknown",I65) -> Kevin Wijaya | K65: P002 | L65: Aerox | M65: 1 | N65: 29800000 | O65: 596000 | P65: 29204000 | Q65: =IF(P65=0,"Batal/Refund","Normal") -> Normal | R65: Kredit - Mandiri Tunas | S65: Lunas | T65: Online - Website | U65: =COUNTIF($A$2:$A$342,A65) -> 1
A66: TRX-1130 | B66: 15 Juli 2026 | C66: =SUBSTITUTE(SUBSTITUTE(SUBSTITUTE(SUBSTITUTE(SUBSTITUTE(SUBSTITUTE(SUBSTITUTE(SUBSTITUTE(SUBSTITUTE(SUBSTITUTE(SUBSTITUTE(SUBSTITUTE(B66," Januari ","/01/")," Februari ","/02/")," Maret ","/03/")," April ","/04/")," Mei ","/05/")," Juni ","/06/")," Juli ","/07/")," Agustus ","/08/")," September ","/09/")," Oktober ","/10/")," November ","/11/")," Desember ","/12/") -> 15/07/2026 | D66: =IFERROR(DATE(VALUE(LEFT(C66,4)),VALUE(MID(C66,6,2)),VALUE(RIGHT(C66,2))),DATE(VALUE(RIGHT(C66,4)),VALUE(MID(C66,4,2)),VALUE(LEFT(C66,2)))) -> 46218 | E66: Karawang | F66: =PROPER(TRIM(SUBSTITUTE(SUBSTITUTE(E66,"Jaksel","Jakarta Selatan"),"Tangerang Kota","Tangerang"))) -> Karawang | G66: Lukman Hakim | H66: =IF(G66="","Unknown",G66) -> Lukman Hakim | I66: Lala Ramadhan | J66: =IF(I66="","Unknown",I66) -> Lala Ramadhan | K66: P004 | L66: Mio | M66: 1 | N66: 18900000 | O66: 567000 | P66: 18333000 | Q66: =IF(P66=0,"Batal/Refund","Normal") -> Normal | R66: Cash | S66: Lunas | T66: Referral | U66: =COUNTIF($A$2:$A$342,A66) -> 1
A67: TRX-1093 | B67: 14 Juli 2026 | C67: =SUBSTITUTE(SUBSTITUTE(SUBSTITUTE(SUBSTITUTE(SUBSTITUTE(SUBSTITUTE(SUBSTITUTE(SUBSTITUTE(SUBSTITUTE(SUBSTITUTE(SUBSTITUTE(SUBSTITUTE(B67," Januari ","/01/")," Februari ","/02/")," Maret ","/03/")," April ","/04/")," Mei ","/05/")," Juni ","/06/")," Juli ","/07/")," Agustus ","/08/")," September ","/09/")," Oktober ","/10/")," November ","/11/")," Desember ","/12/") -> 14/07/2026 | D67: =IFERROR(DATE(VALUE(LEFT(C67,4)),VALUE(MID(C67,6,2)),VALUE(RIGHT(C67,2))),DATE(VALUE(RIGHT(C67,4)),VALUE(MID(C67,4,2)),VALUE(LEFT(C67,2)))) -> 46217 | E67: Sukabumi | F67: =PROPER(TRIM(SUBSTITUTE(SUBSTITUTE(E67,"Jaksel","Jakarta Selatan"),"Tangerang Kota","Tangerang"))) -> Sukabumi | G67: Hadi Santoso | H67: =IF(G67="","Unknown",G67) -> Hadi Santoso | I67: Dewi Hidayat | J67: =IF(I67="","Unknown",I67) -> Dewi Hidayat | K67: P005 | L67: Fazzio | M67: 1 | N67: 21500000 | O67: 430000 | P67: 21070000 | Q67: =IF(P67=0,"Batal/Refund","Normal") -> Normal | R67: Kredit - Mandiri Tunas | S67: Lunas | T67: Referral | U67: =COUNTIF($A$2:$A$342,A67) -> 1
A68: TRX-1030 | B68: 13/07/2026 | C68: =SUBSTITUTE(SUBSTITUTE(SUBSTITUTE(SUBSTITUTE(SUBSTITUTE(SUBSTITUTE(SUBSTITUTE(SUBSTITUTE(SUBSTITUTE(SUBSTITUTE(SUBSTITUTE(SUBSTITUTE(B68," Januari ","/01/")," Februari ","/02/")," Maret ","/03/")," April ","/04/")," Mei ","/05/")," Juni ","/06/")," Juli ","/07/")," Agustus ","/08/")," September ","/09/")," Oktober ","/10/")," November ","/11/")," Desember ","/12/") -> 13/07/2026 | D68: =IFERROR(DATE(VALUE(LEFT(C68,4)),VALUE(MID(C68,6,2)),VALUE(RIGHT(C68,2))),DATE(VALUE(RIGHT(C68,4)),VALUE(MID(C68,4,2)),VALUE(LEFT(C68,2)))) -> 46216 | E68: Sukabumi | F68: =PROPER(TRIM(SUBSTITUTE(SUBSTITUTE(E68,"Jaksel","Jakarta Selatan"),"Tangerang Kota","Tangerang"))) -> Sukabumi | G68: Lukman Hakim | H68: =IF(G68="","Unknown",G68) -> Lukman Hakim | I68: Jihan Firmansyah | J68: =IF(I68="","Unknown",I68) -> Jihan Firmansyah | K68: P006 | L68: Gear | M68: 1 | N68: 17800000 | O68: 178000 | P68: 17622000 | Q68: =IF(P68=0,"Batal/Refund","Normal") -> Normal | R68: Kredit - Adira | S68: Lunas | T68: Referral | U68: =COUNTIF($A$2:$A$342,A68) -> 1
A69: TRX-1059 | B69: 2026-07-14 | C69: =SUBSTITUTE(SUBSTITUTE(SUBSTITUTE(SUBSTITUTE(SUBSTITUTE(SUBSTITUTE(SUBSTITUTE(SUBSTITUTE(SUBSTITUTE(SUBSTITUTE(SUBSTITUTE(SUBSTITUTE(B69," Januari ","/01/")," Februari ","/02/")," Maret ","/03/")," April ","/04/")," Mei ","/05/")," Juni ","/06/")," Juli ","/07/")," Agustus ","/08/")," September ","/09/")," Oktober ","/10/")," November ","/11/")," Desember ","/12/") -> 2026-07-14 | D69: =IFERROR(DATE(VALUE(LEFT(C69,4)),VALUE(MID(C69,6,2)),VALUE(RIGHT(C69,2))),DATE(VALUE(RIGHT(C69,4)),VALUE(MID(C69,4,2)),VALUE(LEFT(C69,2)))) -> 46217 | E69: Bogor | F69: =PROPER(TRIM(SUBSTITUTE(SUBSTITUTE(E69,"Jaksel","Jakarta Selatan"),"Tangerang Kota","Tangerang"))) -> Bogor | G69: Rangga Saputra | H69: =IF(G69="","Unknown",G69) -> Rangga Saputra | I69: Putra Hidayat | J69: =IF(I69="","Unknown",I69) -> Putra Hidayat | K69: P009 | L69: Grand Filano | M69: 1 | N69: 26900000 | O69: 807000 | P69: 26093000 | Q69: =IF(P69=0,"Batal/Refund","Normal") -> Normal | R69: Kredit - Adira | S69: Lunas | T69: Referral | U69: =COUNTIF($A$2:$A$342,A69) -> 1
A70: TRX-1193 | B70: 16/07/2026 | C70: =SUBSTITUTE(SUBSTITUTE(SUBSTITUTE(SUBSTITUTE(SUBSTITUTE(SUBSTITUTE(SUBSTITUTE(SUBSTITUTE(SUBSTITUTE(SUBSTITUTE(SUBSTITUTE(SUBSTITUTE(B70," Januari ","/01/")," Februari ","/02/")," Maret ","/03/")," April ","/04/")," Mei ","/05/")," Juni ","/06/")," Juli ","/07/")," Agustus ","/08/")," September ","/09/")," Oktober ","/10/")," November ","/11/")," Desember ","/12/") -> 16/07/2026 | D70: =IFERROR(DATE(VALUE(LEFT(C70,4)),VALUE(MID(C70,6,2)),VALUE(RIGHT(C70,2))),DATE(VALUE(RIGHT(C70,4)),VALUE(MID(C70,4,2)),VALUE(LEFT(C70,2)))) -> 46219 | E70: Sukabumi | F70: =PROPER(TRIM(SUBSTITUTE(SUBSTITUTE(E70,"Jaksel","Jakarta Selatan"),"Tangerang Kota","Tangerang"))) -> Sukabumi | G70: Vino Bastian G. | H70: =IF(G70="","Unknown",G70) -> Vino Bastian G. | I70: Lala Saputra | J70: =IF(I70="","Unknown",I70) -> Lala Saputra | K70: P004 | L70: Mio | M70: 1 | N70: 18900000 | O70: 189000 | P70: 18711000 | Q70: =IF(P70=0,"Batal/Refund","Normal") -> Normal | R70: Debit/Transfer | S70: Lunas | T70: Pameran | U70: =COUNTIF($A$2:$A$342,A70) -> 1
A71: TRX-1223 | B71: 2026-07-17 | C71: =SUBSTITUTE(SUBSTITUTE(SUBSTITUTE(SUBSTITUTE(SUBSTITUTE(SUBSTITUTE(SUBSTITUTE(SUBSTITUTE(SUBSTITUTE(SUBSTITUTE(SUBSTITUTE(SUBSTITUTE(B71," Januari ","/01/")," Februari ","/02/")," Maret ","/03/")," April ","/04/")," Mei ","/05/")," Juni ","/06/")," Juli ","/07/")," Agustus ","/08/")," September ","/09/")," Oktober ","/10/")," November ","/11/")," Desember ","/12/") -> 2026-07-17 | D71: =IFERROR(DATE(VALUE(LEFT(C71,4)),VALUE(MID(C71,6,2)),VALUE(RIGHT(C71,2))),DATE(VALUE(RIGHT(C71,4)),VALUE(MID(C71,4,2)),VALUE(LEFT(C71,2)))) -> 46220 | E71: Cikarang | F71: =PROPER(TRIM(SUBSTITUTE(SUBSTITUTE(E71,"Jaksel","Jakarta Selatan"),"Tangerang Kota","Tangerang"))) -> Cikarang | G71: Kiki Amelia | H71: =IF(G71="","Unknown",G71) -> Kiki Amelia | I71: Tono Saputra | J71: =IF(I71="","Unknown",I71) -> Tono Saputra | K71: P003 | L71: Lexi | M71: 1 | N71: 27400000 | O71: 0 | P71: 27400000 | Q71: =IF(P71=0,"Batal/Refund","Normal") -> Normal | R71: Cash | S71: DP | T71: Online - Website | U71: =COUNTIF($A$2:$A$342,A71) -> 1
A72: TRX-1278 | B72: 18/07/2026 | C72: =SUBSTITUTE(SUBSTITUTE(SUBSTITUTE(SUBSTITUTE(SUBSTITUTE(SUBSTITUTE(SUBSTITUTE(SUBSTITUTE(SUBSTITUTE(SUBSTITUTE(SUBSTITUTE(SUBSTITUTE(B72," Januari ","/01/")," Februari ","/02/")," Maret ","/03/")," April ","/04/")," Mei ","/05/")," Juni ","/06/")," Juli ","/07/")," Agustus ","/08/")," September ","/09/")," Oktober ","/10/")," November ","/11/")," Desember ","/12/") -> 18/07/2026 | D72: =IFERROR(DATE(VALUE(LEFT(C72,4)),VALUE(MID(C72,6,2)),VALUE(RIGHT(C72,2))),DATE(VALUE(RIGHT(C72,4)),VALUE(MID(C72,4,2)),VALUE(LEFT(C72,2)))) -> 46221 | E72: Jakarta Selatan | F72: =PROPER(TRIM(SUBSTITUTE(SUBSTITUTE(E72,"Jaksel","Jakarta Selatan"),"Tangerang Kota","Tangerang"))) -> Jakarta Selatan | G72: Lukman Hakim | H72: =IF(G72="","Unknown",G72) -> Lukman Hakim | I72: Budi Firmansyah | J72: =IF(I72="","Unknown",I72) -> Budi Firmansyah | K72: P008 | L72: MX King | M72: 1 | N72: 24600000 | O72: 492000 | P72: 24108000 | Q72: =IF(P72=0,"Batal/Refund","Normal") -> Normal | R72: Cash | S72: Lunas | T72: Pameran | U72: =COUNTIF($A$2:$A$342,A72) -> 1
A73: TRX-1295 | B73: 18/07/2026 | C73: =SUBSTITUTE(SUBSTITUTE(SUBSTITUTE(SUBSTITUTE(SUBSTITUTE(SUBSTITUTE(SUBSTITUTE(SUBSTITUTE(SUBSTITUTE(SUBSTITUTE(SUBSTITUTE(SUBSTITUTE(B73," Januari ","/01/")," Februari ","/02/")," Maret ","/03/")," April ","/04/")," Mei ","/05/")," Juni ","/06/")," Juli ","/07/")," Agustus ","/08/")," September ","/09/")," Oktober ","/10/")," November ","/11/")," Desember ","/12/") -> 18/07/2026 | D73: =IFERROR(DATE(VALUE(LEFT(C73,4)),VALUE(MID(C73,6,2)),VALUE(RIGHT(C73,2))),DATE(VALUE(RIGHT(C73,4)),VALUE(MID(C73,4,2)),VALUE(LEFT(C73,2)))) -> 46221 | E73: Sukabumi | F73: =PROPER(TRIM(SUBSTITUTE(SUBSTITUTE(E73,"Jaksel","Jakarta Selatan"),"Tangerang Kota","Tangerang"))) -> Sukabumi | G73: Indah Permata | H73: =IF(G73="","Unknown",G73) -> Indah Permata | I73: Kevin Ramadhan | J73: =IF(I73="","Unknown",I73) -> Kevin Ramadhan | K73: P003 | L73: Lexi | M73: 1 | N73: 27400000 | O73: 822000 | P73: 26578000 | Q73: =IF(P73=0,"Batal/Refund","Normal") -> Normal | R73: Kredit - FIF | S73: DP | T73: Referral | U73: =COUNTIF($A$2:$A$342,A73) -> 1
... A86: TRX-1052 | B86: 2026-07-14 | C86: =SUBSTITUTE(SUBSTITUTE(SUBSTITUTE(SUBSTITUTE(SUBSTITUTE(SUBSTITUTE(SUBSTITUTE(SUBSTITUTE(SUBSTITUTE(SUBSTITUTE(SUBSTITUTE(SUBSTITUTE(B86," Januari ","/01/")," Februari ","/02/")," Maret ","/03/")," April ","/04/")," Mei ","/05/")," Juni ","/06/")," Juli ","/07/")," Agustus ","/08/")," September ","/09/")," Oktober ","/10/")," November ","/11/")," Desember ","/12/") -> 2026-07-14 | D86: =IFERROR(DATE(VALUE(LEFT(C86,4)),VALUE(MID(C86,6,2)),VALUE(RIGHT(C86,2))),DATE(VALUE(RIGHT(C86,4)),VALUE(MID(C86,4,2)),VALUE(LEFT(C86,2)))) -> 46217 | E86: Bandung | F86: =PROPER(TRIM(SUBSTITUTE(SUBSTITUTE(E86,"Jaksel","Jakarta Selatan"),"Tangerang Kota","Tangerang"))) -> Bandung | G86: Rangga Saputra | H86: =IF(G86="","Unknown",G86) -> Rangga Saputra | I86: Citra Ramadhan | J86: =IF(I86="","Unknown",I86) -> Citra Ramadhan | K86: P002 | L86: Aerox | M86: 2 | N86: 29800000 | O86: 596000 | P86: 59004000 | Q86: =IF(P86=0,"Batal/Refund","Normal") -> Normal | R86: Kredit - Adira | S86: Lunas | T86: Online - Website | U86: =COUNTIF($A$2:$A$342,A86) -> 1
A87: TRX-1010 | B87: 13 Juli 2026 | C87: =SUBSTITUTE(SUBSTITUTE(SUBSTITUTE(SUBSTITUTE(SUBSTITUTE(SUBSTITUTE(SUBSTITUTE(SUBSTITUTE(SUBSTITUTE(SUBSTITUTE(SUBSTITUTE(SUBSTITUTE(B87," Januari ","/01/")," Februari ","/02/")," Maret ","/03/")," April ","/04/")," Mei ","/05/")," Juni ","/06/")," Juli ","/07/")," Agustus ","/08/")," September ","/09/")," Oktober ","/10/")," November ","/11/")," Desember ","/12/") -> 13/07/2026 | D87: =IFERROR(DATE(VALUE(LEFT(C87,4)),VALUE(MID(C87,6,2)),VALUE(RIGHT(C87,2))),DATE(VALUE(RIGHT(C87,4)),VALUE(MID(C87,4,2)),VALUE(LEFT(C87,2)))) -> 46216 | E87: Depok | F87: =PROPER(TRIM(SUBSTITUTE(SUBSTITUTE(E87,"Jaksel","Jakarta Selatan"),"Tangerang Kota","Tangerang"))) -> Depok | H87: =IF(G87="","Unknown",G87) -> Unknown | I87: Lala Lestari | J87: =IF(I87="","Unknown",I87) -> Lala Lestari | K87: P010 | L87: Freego | M87: 1 | N87: 22300000 | O87: 0 | P87: 22300000 | Q87: =IF(P87=0,"Batal/Refund","Normal") -> Normal | R87: Cash | S87: Lunas | T87: Showroom | U87: =COUNTIF($A$2:$A$342,A87) -> 1
A88: TRX-1276 | B88: 2026-07-18 | C88: =SUBSTITUTE(SUBSTITUTE(SUBSTITUTE(SUBSTITUTE(SUBSTITUTE(SUBSTITUTE(SUBSTITUTE(SUBSTITUTE(SUBSTITUTE(SUBSTITUTE(SUBSTITUTE(SUBSTITUTE(B88," Januari ","/01/")," Februari ","/02/")," Maret ","/03/")," April ","/04/")," Mei ","/05/")," Juni ","/06/")," Juli ","/07/")," Agustus ","/08/")," September ","/09/")," Oktober ","/10/")," November ","/11/")," Desember ","/12/") -> 2026-07-18 | D88: =IFERROR(DATE(VALUE(LEFT(C88,4)),VALUE(MID(C88,6,2)),VALUE(RIGHT(C88,2))),DATE(VALUE(RIGHT(C88,4)),VALUE(MID(C88,4,2)),VALUE(LEFT(C88,2)))) -> 46221 | E88: Jakarta Selatan | F88: =PROPER(TRIM(SUBSTITUTE(SUBSTITUTE(E88,"Jaksel","Jakarta Selatan"),"Tangerang Kota","Tangerang"))) -> Jakarta Selatan | G88: Sari Dewi | H88: =IF(G88="","Unknown",G88) -> Sari Dewi | I88: Siska Maharani | J88: =IF(I88="","Unknown",I88) -> Siska Maharani | K88: P001 | L88: NMAX | M88: 1 | N88: 33500000 | O88: 335000 | P88: 0 | Q88: =IF(P88=0,"Batal/Refund","Normal") -> Batal/Refund | R88: Debit/Transfer | S88: Proses Kredit | T88: Showroom | U88: =COUNTIF($A$2:$A$342,A88) -> 1
A89: TRX-1017 | B89: 2026-07-13 | C89: =SUBSTITUTE(SUBSTITUTE(SUBSTITUTE(SUBSTITUTE(SUBSTITUTE(SUBSTITUTE(SUBSTITUTE(SUBSTITUTE(SUBSTITUTE(SUBSTITUTE(SUBSTITUTE(SUBSTITUTE(B89," Januari ","/01/")," Februari ","/02/")," Maret ","/03/")," April ","/04/")," Mei ","/05/")," Juni ","/06/")," Juli ","/07/")," Agustus ","/08/")," September ","/09/")," Oktober ","/10/")," November ","/11/")," Desember ","/12/") -> 2026-07-13 | D89: =IFERROR(DATE(VALUE(LEFT(C89,4)),VALUE(MID(C89,6,2)),VALUE(RIGHT(C89,2))),DATE(VALUE(RIGHT(C89,4)),VALUE(MID(C89,4,2)),VALUE(LEFT(C89,2)))) -> 46216 | E89: Jakarta Timur | F89: =PROPER(TRIM(SUBSTITUTE(SUBSTITUTE(E89,"Jaksel","Jakarta Selatan"),"Tangerang Kota","Tangerang"))) -> Jakarta Timur | G89: Taufik Hidayat | H89: =IF(G89="","Unknown",G89) -> Taufik Hidayat | I89: Putra Kusuma | J89: =IF(I89="","Unknown",I89) -> Putra Kusuma | K89: P009 | L89: Grand Filano | M89: 1 | N89: 26900000 | O89: 269000 | P89: 26631000 | Q89: =IF(P89=0,"Batal/Refund","Normal") -> Normal | R89: Debit/Transfer | S89: Lunas | T89: Showroom | U89: =COUNTIF($A$2:$A$342,A89) -> 1
A90: TRX-1248 | B90: 2026-07-18 | C90: =SUBSTITUTE(SUBSTITUTE(SUBSTITUTE(SUBSTITUTE(SUBSTITUTE(SUBSTITUTE(SUBSTITUTE(SUBSTITUTE(SUBSTITUTE(SUBSTITUTE(SUBSTITUTE(SUBSTITUTE(B90," Januari ","/01/")," Februari ","/02/")," Maret ","/03/")," April ","/04/")," Mei ","/05/")," Juni ","/06/")," Juli ","/07/")," Agustus ","/08/")," September ","/09/")," Oktober ","/10/")," November ","/11/")," Desember ","/12/") -> 2026-07-18 | D90: =IFERROR(DATE(VALUE(LEFT(C90,4)),VALUE(MID(C90,6,2)),VALUE(RIGHT(C90,2))),DATE(VALUE(RIGHT(C90,4)),VALUE(MID(C90,4,2)),VALUE(LEFT(C90,2)))) -> 46221 | E90: Bandung | F90: =PROPER(TRIM(SUBSTITUTE(SUBSTITUTE(E90,"Jaksel","Jakarta Selatan"),"Tangerang Kota","Tangerang"))) -> Bandung | G90: Oki Setiawan | H90: =IF(G90="","Unknown",G90) -> Oki Setiawan | I90: Putra Maharani | J90: =IF(I90="","Unknown",I90) -> Putra Maharani | K90: P007 | L90: XSR 155 | M90: 1 | N90: 41000000 | O90: 1230000 | P90: 39770000 | Q90: =IF(P90=0,"Batal/Refund","Normal") -> Normal | R90: Kredit - Mandiri Tunas | S90: Lunas | T90: Online - Website | U90: =COUNTIF($A$2:$A$342,A90) -> 1
A91: TRX-1001 | B91: 13 Juli 2026 | C91: =SUBSTITUTE(SUBSTITUTE(SUBSTITUTE(SUBSTITUTE(SUBSTITUTE(SUBSTITUTE(SUBSTITUTE(SUBSTITUTE(SUBSTITUTE(SUBSTITUTE(SUBSTITUTE(SUBSTITUTE(B91," Januari ","/01/")," Februari ","/02/")," Maret ","/03/")," April ","/04/")," Mei ","/05/")," Juni ","/06/")," Juli ","/07/")," Agustus ","/08/")," September ","/09/")," Oktober ","/10/")," November ","/11/")," Desember ","/12/") -> 13/07/2026 | D91: =IFERROR(DATE(VALUE(LEFT(C91,4)),VALUE(MID(C91,6,2)),VALUE(RIGHT(C91,2))),DATE(VALUE(RIGHT(C91,4)),VALUE(MID(C91,4,2)),VALUE(LEFT(C91,2)))) -> 46216 | E91: Tangerang | F91: =PROPER(TRIM(SUBSTITUTE(SUBSTITUTE(E91,"Jaksel","Jakarta Selatan"),"Tangerang Kota","Tangerang"))) -> Tangerang | G91: Taufik Hidayat | H91: =IF(G91="","Unknown",G91) -> Taufik Hidayat | I91: Nia Saputra | J91: =IF(I91="","Unknown",I91) -> Nia Saputra | K91: P002 | L91: Aerox | M91: 1 | N91: 29800000 | O91: 1490000 | P91: 28310000 | Q91: =IF(P91=0,"Batal/Refund","Normal") -> Normal | R91: Debit/Transfer | S91: Lunas | T91: Online - Website | U91: =COUNTIF($A$2:$A$342,A91) -> 1
A92: TRX-1159 | B92: 16 Juli 2026 | C92: =SUBSTITUTE(SUBSTITUTE(SUBSTITUTE(SUBSTITUTE(SUBSTITUTE(SUBSTITUTE(SUBSTITUTE(SUBSTITUTE(SUBSTITUTE(SUBSTITUTE(SUBSTITUTE(SUBSTITUTE(B92," Januari ","/01/")," Februari ","/02/")," Maret ","/03/")," April ","/04/")," Mei ","/05/")," Juni ","/06/")," Juli ","/07/")," Agustus ","/08/")," September ","/09/")," Oktober ","/10/")," November ","/11/")," Desember ","/12/") -> 16/07/2026 | D92: =IFERROR(DATE(VALUE(LEFT(C92,4)),VALUE(MID(C92,6,2)),VALUE(RIGHT(C92,2))),DATE(VALUE(RIGHT(C92,4)),VALUE(MID(C92,4,2)),VALUE(LEFT(C92,2)))) -> 46219 | E92: Bandung | F92: =PROPER(TRIM(SUBSTITUTE(SUBSTITUTE(E92,"Jaksel","Jakarta Selatan"),"Tangerang Kota","Tangerang"))) -> Bandung | G92: Vino Bastian G. | H92: =IF(G92="","Unknown",G92) -> Vino Bastian G. | I92: Kevin Pratama | J92: =IF(I92="","Unknown",I92) -> Kevin Pratama | K92: P002 | L92: Aerox | M92: 1 | N92: 29800000 | O92: 894000 | P92: 28906000 | Q92: =IF(P92=0,"Batal/Refund","Normal") -> Normal | R92: Kredit - Adira | S92: Lunas | T92: Pameran | U92: =COUNTIF($A$2:$A$342,A92) -> 1
A93: TRX-1139 | B93: 15/07/2026 | C93: =SUBSTITUTE(SUBSTITUTE(SUBSTITUTE(SUBSTITUTE(SUBSTITUTE(SUBSTITUTE(SUBSTITUTE(SUBSTITUTE(SUBSTITUTE(SUBSTITUTE(SUBSTITUTE(SUBSTITUTE(B93," Januari ","/01/")," Februari ","/02/")," Maret ","/03/")," April ","/04/")," Mei ","/05/")," Juni ","/06/")," Juli ","/07/")," Agustus ","/08/")," September ","/09/")," Oktober ","/10/")," November ","/11/")," Desember ","/12/") -> 15/07/2026 | D93: =IFERROR(DATE(VALUE(LEFT(C93,4)),VALUE(MID(C93,6,2)),VALUE(RIGHT(C93,2))),DATE(VALUE(RIGHT(C93,4)),VALUE(MID(C93,4,2)),VALUE(LEFT(C93,2)))) -> 46218 | E93: Sukabumi | F93: =PROPER(TRIM(SUBSTITUTE(SUBSTITUTE(E93,"Jaksel","Jakarta Selatan"),"Tangerang Kota","Tangerang"))) -> Sukabumi | G93: Lukman Hakim | H93: =IF(G93="","Unknown",G93) -> Lukman Hakim | I93: Nia Pratama | J93: =IF(I93="","Unknown",I93) -> Nia Pratama | K93: P004 | L93: Mio | M93: 1 | N93: 18900000 | O93: 0 | P93: 18900000 | Q93: =IF(P93=0,"Batal/Refund","Normal") -> Normal | R93: Cash | S93: Lunas | T93: Online - Website | U93: =COUNTIF($A$2:$A$342,A93) -> 1
A94: TRX-1063 | B94: 2026-07-14 | C94: =SUBSTITUTE(SUBSTITUTE(SUBSTITUTE(SUBSTITUTE(SUBSTITUTE(SUBSTITUTE(SUBSTITUTE(SUBSTITUTE(SUBSTITUTE(SUBSTITUTE(SUBSTITUTE(SUBSTITUTE(B94," Januari ","/01/")," Februari ","/02/")," Maret ","/03/")," April ","/04/")," Mei ","/05/")," Juni ","/06/")," Juli ","/07/")," Agustus ","/08/")," September ","/09/")," Oktober ","/10/")," November ","/11/")," Desember ","/12/") -> 2026-07-14 | D94: =IFERROR(DATE(VALUE(LEFT(C94,4)),VALUE(MID(C94,6,2)),VALUE(RIGHT(C94,2))),DATE(VALUE(RIGHT(C94,4)),VALUE(MID(C94,4,2)),VALUE(LEFT(C94,2)))) -> 46217 | E94: Cikarang | F94: =PROPER(TRIM(SUBSTITUTE(SUBSTITUTE(E94,"Jaksel","Jakarta Selatan"),"Tangerang Kota","Tangerang"))) -> Cikarang | G94: Kiki Amelia | H94: =IF(G94="","Unknown",G94) -> Kiki Amelia | I94: Irfan Ramadhan | J94: =IF(I94="","Unknown",I94) -> Irfan Ramadhan | K94: P003 | L94: Lexi | M94: 1 | N94: 27400000 | O94: 0 | P94: 27400000 | Q94: =IF(P94=0,"Batal/Refund","Normal") -> Normal | R94: Kredit - Mandiri Tunas | S94: Proses Kredit | T94: Online - Website | U94: =COUNTIF($A$2:$A$342,A94) -> 1
A95: TRX-1329 | B95: 2026-07-19 | C95: =SUBSTITUTE(SUBSTITUTE(SUBSTITUTE(SUBSTITUTE(SUBSTITUTE(SUBSTITUTE(SUBSTITUTE(SUBSTITUTE(SUBSTITUTE(SUBSTITUTE(SUBSTITUTE(SUBSTITUTE(B95," Januari ","/01/")," Februari ","/02/")," Maret ","/03/")," April ","/04/")," Mei ","/05/")," Juni ","/06/")," Juli ","/07/")," Agustus ","/08/")," September ","/09/")," Oktober ","/10/")," November ","/11/")," Desember ","/12/") -> 2026-07-19 | D95: =IFERROR(DATE(VALUE(LEFT(C95,4)),VALUE(MID(C95,6,2)),VALUE(RIGHT(C95,2))),DATE(VALUE(RIGHT(C95,4)),VALUE(MID(C95,4,2)),VALUE(LEFT(C95,2)))) -> 46222 | E95: Jakarta Selatan | F95: =PROPER(TRIM(SUBSTITUTE(SUBSTITUTE(E95,"Jaksel","Jakarta Selatan"),"Tangerang Kota","Tangerang"))) -> Jakarta Selatan | G95: Rudi Hartono | H95: =IF(G95="","Unknown",G95) -> Rudi Hartono | I95: Irfan Wijaya | J95: =IF(I95="","Unknown",I95) -> Irfan Wijaya | K95: P010 | L95: Freego | M95: 1 | N95: 22300000 | O95: 446000 | P95: 21854000 | Q95: =IF(P95=0,"Batal/Refund","Normal") -> Normal | R95: Kredit - Adira | S95: Lunas | T95: Referral | U95: =COUNTIF($A$2:$A$342,A95) -> 1
A96: TRX-1160 | B96: 16/07/2026 | C96: =SUBSTITUTE(SUBSTITUTE(SUBSTITUTE(SUBSTITUTE(SUBSTITUTE(SUBSTITUTE(SUBSTITUTE(SUBSTITUTE(SUBSTITUTE(SUBSTITUTE(SUBSTITUTE(SUBSTITUTE(B96," Januari ","/01/")," Februari ","/02/")," Maret ","/03/")," April ","/04/")," Mei ","/05/")," Juni ","/06/")," Juli ","/07/")," Agustus ","/08/")," September ","/09/")," Oktober ","/10/")," November ","/11/")," Desember ","/12/") -> 16/07/2026 | D96: =IFERROR(DATE(VALUE(LEFT(C96,4)),VALUE(MID(C96,6,2)),VALUE(RIGHT(C96,2))),DATE(VALUE(RIGHT(C96,4)),VALUE(MID(C96,4,2)),VALUE(LEFT(C96,2)))) -> 46219 | E96: Bandung | F96: =PROPER(TRIM(SUBSTITUTE(SUBSTITUTE(E96,"Jaksel","Jakarta Selatan"),"Tangerang Kota","Tangerang"))) -> Bandung | G96: Gita Ayu | H96: =IF(G96="","Unknown",G96) -> Gita Ayu | I96: Nia Firmansyah | J96: =IF(I96="","Unknown",I96) -> Nia Firmansyah | K96: P002 | L96: Aerox | M96: 1 | N96: 29800000 | O96: 894000 | P96: 28906000 | Q96: =IF(P96=0,"Batal/Refund","Normal") -> Normal | R96: Debit/Transfer | S96: Proses Kredit | T96: Referral | U96: =COUNTIF($A$2:$A$342,A96) -> 1
A97: TRX-1198 | B97: 16 Juli 2026 | C97: =SUBSTITUTE(SUBSTITUTE(SUBSTITUTE(SUBSTITUTE(SUBSTITUTE(SUBSTITUTE(SUBSTITUTE(SUBSTITUTE(SUBSTITUTE(SUBSTITUTE(SUBSTITUTE(SUBSTITUTE(B97," Januari ","/01/")," Februari ","/02/")," Maret ","/03/")," April ","/04/")," Mei ","/05/")," Juni ","/06/")," Juli ","/07/")," Agustus ","/08/")," September ","/09/")," Oktober ","/10/")," November ","/11/")," Desember ","/12/") -> 16/07/2026 | D97: =IFERROR(DATE(VALUE(LEFT(C97,4)),VALUE(MID(C97,6,2)),VALUE(RIGHT(C97,2))),DATE(VALUE(RIGHT(C97,4)),VALUE(MID(C97,4,2)),VALUE(LEFT(C97,2)))) -> 46219 | E97: Sukabumi | F97: =PROPER(TRIM(SUBSTITUTE(SUBSTITUTE(E97,"Jaksel","Jakarta Selatan"),"Tangerang Kota","Tangerang"))) -> Sukabumi | G97: Lukman Hakim | H97: =IF(G97="","Unknown",G97) -> Lukman Hakim | I97: Jihan Lestari | J97: =IF(I97="","Unknown",I97) -> Jihan Lestari | K97: P004 | L97: Mio | M97: 1 | N97: 18900000 | O97: 567000 | P97: 18333000 | Q97: =IF(P97=0,"Batal/Refund","Normal") -> Normal | R97: Cash | S97: Proses Kredit | T97: Online - Website | U97: =COUNTIF($A$2:$A$342,A97) -> 1
A98: TRX-1071 | B98: 14/07/2026 | C98: =SUBSTITUTE(SUBSTITUTE(SUBSTITUTE(SUBSTITUTE(SUBSTITUTE(SUBSTITUTE(SUBSTITUTE(SUBSTITUTE(SUBSTITUTE(SUBSTITUTE(SUBSTITUTE(SUBSTITUTE(B98," Januari ","/01/")," Februari ","/02/")," Maret ","/03/")," April ","/04/")," Mei ","/05/")," Juni ","/06/")," Juli ","/07/")," Agustus ","/08/")," September ","/09/")," Oktober ","/10/")," November ","/11/")," Desember ","/12/") -> 14/07/2026 | D98: =IFERROR(DATE(VALUE(LEFT(C98,4)),VALUE(MID(C98,6,2)),VALUE(RIGHT(C98,2))),DATE(VALUE(RIGHT(C98,4)),VALUE(MID(C98,4,2)),VALUE(LEFT(C98,2)))) -> 46217 | E98: Jakarta Timur | F98: =PROPER(TRIM(SUBSTITUTE(SUBSTITUTE(E98,"Jaksel","Jakarta Selatan"),"Tangerang Kota","Tangerang"))) -> Jakarta Timur | G98: Rudi Hartono | H98: =IF(G98="","Unknown",G98) -> Rudi Hartono | I98: Oscar Lestari | J98: =IF(I98="","Unknown",I98) -> Oscar Lestari | K98: P002 | L98: Aerox | M98: 1 | N98: 29800000 | O98: 596000 | P98: 29204000 | Q98: =IF(P98=0,"Batal/Refund","Normal") -> Normal | R98: Debit/Transfer | S98: Lunas | T98: Referral | U98: =COUNTIF($A$2:$A$342,A98) -> 1
...

Sheet Clean Sales Transaction
A1: Transaction ID | B1: Date | C1: Branch | D1: Sales Rep | E1: Custumer Name | F1: Product Code | G1: Product Name | H1: Qty | I1: Unit Price | J1: Discount | K1: Total Sales | L1: Status Transaksi | M1: Payment Method | N1: Payment Status | O1: Channel
A2: TRX-1086 | B2: 46217 | C2: Cibubur | D2: Taufik Hidayat | E2: Galih Ramadhan | F2: P001 | G2: NMAX | H2: 1 | I2: 33500000 | J2: 1675000 | K2: 31825000 | L2: Normal | M2: Kredit - Mandiri Tunas | N2: Lunas | O2: Pameran
A3: TRX-1192 | B3: 46219 | C3: Sukabumi | D3: Vino Bastian G. | E3: Made Ramadhan | F3: P001 | G3: NMAX | H3: 1 | I3: 33500000 | J3: 1005000 | K3: 32495000 | L3: Normal | M3: Debit/Transfer | N3: Lunas | O3: Online - Website
A4: TRX-1108 | B4: 46218 | C4: Depok | D4: Joko Widodo S. | E4: Putra Hidayat | F4: P010 | G4: Freego | H4: 1 | I4: 22300000 | J4: 669000 | K4: 21631000 | L4: Normal | M4: Cash | N4: Lunas | O4: Referral
A5: TRX-1106 | B5: 46218 | C5: Depok | D5: Lina Marlina | E5: Hana Anggraini | F5: P008 | G5: MX King | H5: 1 | I5: 24600000 | J5: 0 | K5: 24600000 | L5: Normal | M5: Kredit - Adira | N5: Lunas | O5: Online - Website
A6: TRX-1124 | B6: 46218 | C6: Jakarta Selatan | D6: Fajar Nugraha | E6: Putra Saputra | F6: P007 | G6: XSR 155 | H6: 1 | I6: 41000000 | J6: 0 | K6: 41000000 | L6: Normal | M6: Debit/Transfer | N6: Lunas | O6: Online - Website
A7: TRX-1094 | B7: 46217 | C7: Sukabumi | D7: Hadi Santoso | E7: Galih Kusuma | F7: P001 | G7: NMAX | H7: 1 | I7: 33500000 | J7: 1005000 | K7: 32495000 | L7: Normal | M7: Cash | N7: Lunas | O7: Pameran
A8: TRX-1115 | B8: 46218 | C8: Bogor | D8: Lukman Hakim | E8: Lala Firmansyah | F8: P006 | G8: Gear | H8: 1 | I8: 17800000 | J8: 534000 | K8: 17266000 | L8: Normal | M8: Kredit - Mandiri Tunas | N8: Lunas | O8: Online - Website
A9: TRX-1012 | B9: 46216 | C9: Bandung | D9: Puji Lestari | E9: Oscar Wijaya | F9: P006 | G9: Gear | H9: 1 | I9: 17800000 | J9: 890000 | K9: 16910000 | L9: Normal | M9: Debit/Transfer | N9: Lunas | O9: Online - Website
A10: TRX-1148 | B10: 46219 | C10: Bekasi | D10: Sari Dewi | E10: Made Wijaya | F10: P001 | G10: NMAX | H10: 1 | I10: 33500000 | J10: 670000 | K10: 32830000 | L10: Normal | M10: Cash | N10: Lunas | O10: Referral
A11: TRX-1213 | B11: 46220 | C11: Depok | D11: Eka Putri | E11: Ahmad Hidayat | F11: P001 | G11: NMAX | H11: 1 | I11: 33500000 | J11: 335000 | K11: 33165000 | L11: Normal | M11: Kredit - FIF | N11: Lunas | O11: Showroom
A12: TRX-1340 | B12: 46222 | C12: Cibubur | D12: Kiki Amelia | E12: Eko Kusuma | F12: P007 | G12: XSR 155 | H12: 1 | I12: 41000000 | J12: 0 | K12: 41000000 | L12: Normal | M12: Debit/Transfer | N12: DP | O12: Pameran
A13: TRX-1132 | B13: 46218 | C13: Karawang | D13: Kiki Amelia | E13: Citra Ramadhan | F13: P001 | G13: NMAX | H13: 1 | I13: 33500000 | J13: 1005000 | K13: 32495000 | L13: Normal | M13: Debit/Transfer | N13: Proses Kredit | O13: Referral
... A342: TRX-1038 | B342: 46217 | C342: Bekasi | D342: Oki Setiawan | E342: Rendi Maharani | F342: P001 | G342: NMAX | H342: 1 | I342: 33500000 | J342: 670000 | K342: 32830000 | L342: Normal | M342: Cash | N342: Lunas | O342: Pameran

Sheet Target vs Actual
A1: Status Transaksi | B1: Normal
D2: Actual Sales per Cabang
A3: Row Labels | B3: Sum of Total Sales | D3: Target Revenue | E3: Achievement % | G3: Row Labels | H3: Sum of Total Sales | J3: Target Revenue | K3: Achievement %
A4: Bandung | B4: 906597000 | D4: =SUMIFS('Target Sales'!D:D,'Target Sales'!A:A,A4) -> 520000000 | E4: =B4/D4 -> 1.7434558 | G4: Bandung | H4: 906597000 | J4: 520000000 | K4: 1.7434558
A5: Bekasi | B5: 923721000 | D5: =SUMIFS('Target Sales'!D:D,'Target Sales'!A:A,A5) -> 260000000 | E5: =B5/D5 -> 3.5527731 | G5: Bekasi | H5: 923721000 | J5: 260000000 | K5: 3.5527731
A6: Bogor | B6: 598845000 | D6: =SUMIFS('Target Sales'!D:D,'Target Sales'!A:A,A6) -> 208000000 | E6: =B6/D6 -> 2.8790625 | G6: Bogor | H6: 598845000 | J6: 208000000 | K6: 2.8790625
A7: Cibubur | B7: 800267000 | D7: =SUMIFS('Target Sales'!D:D,'Target Sales'!A:A,A7) -> 468000000 | E7: =B7/D7 -> 1.7099722 | G7: Cibubur | H7: 800267000 | J7: 468000000 | K7: 1.7099722
A8: Cikarang | B8: 760218000 | D8: =SUMIFS('Target Sales'!D:D,'Target Sales'!A:A,A8) -> 260000000 | E8: =B8/D8 -> 2.9239154 | G8: Cikarang | H8: 760218000 | J8: 260000000 | K8: 2.9239154
A9: Depok | B9: 768832000 | D9: =SUMIFS('Target Sales'!D:D,'Target Sales'!A:A,A9) -> 260000000 | E9: =B9/D9 -> 2.9570462 | G9: Depok | H9: 768832000 | J9: 260000000 | K9: 2.9570462
A10: Jakarta Selatan | B10: 918489000 | D10: =SUMIFS('Target Sales'!D:D,'Target Sales'!A:A,A10) -> 468000000 | E10: =B10/D10 -> 1.9625833 | G10: Jakarta Selatan | H10: 918489000 | J10: 468000000 | K10: 1.9625833
A11: Jakarta Timur | B11: 532139000 | D11: =SUMIFS('Target Sales'!D:D,'Target Sales'!A:A,A11) -> 260000000 | E11: =B11/D11 -> 2.0466885 | G11: Jakarta Timur | H11: 532139000 | J11: 260000000 | K11: 2.0466885
A12: Karawang | B12: 862042000 | D12: =SUMIFS('Target Sales'!D:D,'Target Sales'!A:A,A12) -> 312000000 | E12: =B12/D12 -> 2.7629551 | G12: Karawang | H12: 862042000 | J12: 312000000 | K12: 2.7629551
A13: Serang | B13: 650659000 | D13: =SUMIFS('Target Sales'!D:D,'Target Sales'!A:A,A13) -> 468000000 | E13: =B13/D13 -> 1.390297 | G13: Serang | H13: 650659000 | J13: 468000000 | K13: 1.390297
A14: Sukabumi | B14: 924626000 | D14: =SUMIFS('Target Sales'!D:D,'Target Sales'!A:A,A14) -> 468000000 | E14: =B14/D14 -> 1.9756966 | G14: Sukabumi | H14: 924626000 | J14: 468000000 | K14: 1.9756966
A15: Tangerang | B15: 787054000 | D15: =SUMIFS('Target Sales'!D:D,'Target Sales'!A:A,A15) -> 364000000 | E15: =B15/D15 -> 2.1622363 | G15: Tangerang | H15: 787054000 | J15: 364000000 | K15: 2.1622363
A16: Grand Total | B16: 9433489000 | G16: Grand Total | H16: 9433489000

Sheet Product Performance
A1: Status Transaksi | B1: Normal
A3: Row Labels | B3: Sum of Total Sales | C3: Sum of Qty | E3: Row Labels | F3: Sum of Total Sales | G3: Sum of Qty
A4: NMAX | B4: 2631760000 | C4: 80 | E4: NMAX | F4: 2631760000 | G4: 80
A5: Aerox | B5: 1811542000 | C5: 62 | E5: Aerox | F5: 1811542000 | G5: 62
A6: Lexi | B6: 1025034000 | C6: 38 | E6: Lexi | F6: 1025034000 | G6: 38
A7: Fazzio | B7: 691225000 | C7: 33 | E7: Fazzio | F7: 691225000 | G7: 33
A8: XSR 155 | B8: 683880000 | C8: 17 | E8: XSR 155 | F8: 683880000 | G8: 17
A9: MX King | B9: 652638000 | C9: 27 | E9: MX King | F9: 652638000 | G9: 27
A10: Mio | B10: 574938000 | C10: 31 | E10: Mio | F10: 574938000 | G10: 31
A11: Grand Filano | B11: 475323000 | C11: 18 | E11: Grand Filano | F11: 475323000 | G11: 18
A12: Gear | B12: 471700000 | C12: 27 | E12: Gear | F12: 471700000 | G12: 27
A13: Freego | B13: 415449000 | C13: 19 | E13: Freego | F13: 415449000 | G13: 19
A14: Grand Total | B14: 9433489000 | C14: 352

Sheet Sales Rep Performance
A1: Status Transaksi | B1: Normal
A3: Row Labels | B3: Count of Transaction ID | C3: Sum of Total Sales | D3: Sum of Qty | F3: Row Labels | G3: Count of Transaction ID | H3: Sum of Total Sales | I3: Sum of Qty
A4: Lukman Hakim | B4: 27 | C4: 668561000 | D4: 30 | F4: Lukman Hakim | G4: 27 | H4: 668561000 | I4: 30
A5: Kiki Amelia | B5: 20 | C5: 566792000 | D5: 20 | F5: Kiki Amelia | G5: 20 | H5: 566792000 | I5: 20
A6: Rangga Saputra | B6: 20 | C6: 554821000 | D6: 21 | F6: Rangga Saputra | G6: 20 | H6: 554821000 | I6: 21
A7: Sari Dewi | B7: 19 | C7: 538697000 | D7: 20 | F7: Sari Dewi | G7: 19 | H7: 538697000 | I7: 20
A8: Taufik Hidayat | B8: 19 | C8: 524072000 | D8: 19 | F8: Taufik Hidayat | G8: 19 | H8: 524072000 | I8: 19
A9: Puji Lestari | B9: 17 | C9: 522417000 | D9: 18 | F9: Puji Lestari | G9: 17 | H9: 522417000 | I9: 18
A10: Umi Kalsum | B10: 19 | C10: 507562000 | D10: 20 | F10: Umi Kalsum | G10: 19 | H10: 507562000 | I10: 20
A11: Joko Widodo S. | B11: 17 | C11: 490679000 | D11: 18 | F11: Joko Widodo S. | G11: 17 | H11: 490679000 | I11: 18
A12: Indah Permata | B12: 17 | C12: 478850000 | D12: 19 | F12: Indah Permata | G12: 17 | H12: 478850000 | I12: 19
A13: Hadi Santoso | B13: 18 | C13: 466106000 | D13: 18 | F13: Hadi Santoso | G13: 18 | H13: 466106000 | I13: 18
A14: Fajar Nugraha | B14: 15 | C14: 453537000 | D14: 16 | F14: Fajar Nugraha | G14: 15 | H14: 453537000 | I14: 16
A15: Vino Bastian G. | B15: 17 | C15: 451581000 | D15: 17 | F15: Vino Bastian G. | G15: 17 | H15: 451581000 | I15: 17
... A24: Rudi Hartono | B24: 9 | C24: 261338000 | D24: 10 | F24: Rudi Hartono | G24: 9 | H24: 261338000 | I24: 10
A25: Grand Total | B25: 336 | C25: 9433489000 | D25: 352

Sheet Dashboard
G2: SALES PERFORMANCE REPORT — MINGGU 29 (13-19 JULI 2026)
E4: TOTAL REVENUE | J4: TOTAL UNIT TERJUAL | N4: AVG ACHIEVEMENT %
E5: =SUM('Clean Sales Transaction'!K:K) -> 9433489000 | J5: =SUMIFS('Clean Sales Transaction'!H:H,'Clean Sales Transaction'!L:L,"Normal") -> 352 | N5: =AVERAGE('Target vs Actual'!E4:E15) -> 2.3388902

Sheet Target Sales
A1: Branch | B1: Week | C1: Target Unit | D1: Target Revenue
A2: Tangerang | B2: 2026-W29 (13-19 Jul 2026) | C2: 14 | D2: 364000000
A3: Bekasi | B3: 2026-W29 (13-19 Jul 2026) | C3: 10 | D3: 260000000
A4: Depok | B4: 2026-W29 (13-19 Jul 2026) | C4: 10 | D4: 260000000
